<?xml version="1.0" ?>
<robot name="jamie" xmlns:xacro="http://www.ros.org/wiki/xacro">

<xacro:include filename="$(find jamie_description)/urdf/materials.xacro" />
<xacro:include filename="$(find jamie_description)/urdf/jamie.trans" />
<xacro:include filename="$(find jamie_description)/urdf/jamie.gazebo" />
<link name="base_link">
  <inertial>
    <origin xyz="-0.011688232223622823 -0.04997378243790669 -0.12088695327313781" rpy="0 0 0"/>
    <mass value="0.8307183918921939"/>
    <inertia ixx="0.000743" iyy="0.00316" izz="0.00283" ixy="0.0" iyz="3.2e-05" ixz="-0.0"/>
  </inertial>
  <visual>
    <origin xyz="0 0 0" rpy="0 0 0"/>
    <geometry>
      <mesh filename="package://jamie_description/meshes/base_link.stl" scale="0.001 0.001 0.001"/>
    </geometry>
    <material name="silver"/>
  </visual>
  <collision>
    <origin xyz="0 0 0" rpy="0 0 0"/>
    <geometry>
      <mesh filename="package://jamie_description/meshes/base_link.stl" scale="0.001 0.001 0.001"/>
    </geometry>
  </collision>
</link>

<link name="right_shoulder_link_1">
  <inertial>
    <origin xyz="0.0006454512302885018 0.020091817000003336 -0.018619059739400937" rpy="0 0 0"/>
    <mass value="0.18884280500199657"/>
    <inertia ixx="7.8e-05" iyy="7.4e-05" izz="5.8e-05" ixy="-0.0" iyz="6e-06" ixz="1e-06"/>
  </inertial>
  <visual>
    <origin xyz="-0.096988 0.053371 -0.133732" rpy="0 0 0"/>
    <geometry>
      <mesh filename="package://jamie_description/meshes/right_shoulder_link_1.stl" scale="0.001 0.001 0.001"/>
    </geometry>
    <material name="silver"/>
  </visual>
  <collision>
    <origin xyz="-0.096988 0.053371 -0.133732" rpy="0 0 0"/>
    <geometry>
      <mesh filename="package://jamie_description/meshes/right_shoulder_link_1.stl" scale="0.001 0.001 0.001"/>
    </geometry>
  </collision>
</link>

<link name="left_shoulder_link_1">
  <inertial>
    <origin xyz="-0.0006456556927465912 0.018983384150954692 -0.019747857797348778" rpy="0 0 0"/>
    <mass value="0.1888429783699795"/>
    <inertia ixx="7.8e-05" iyy="7.5e-05" izz="5.8e-05" ixy="0.0" iyz="5e-06" ixz="-1e-06"/>
  </inertial>
  <visual>
    <origin xyz="0.118164 0.053179 -0.133793" rpy="0 0 0"/>
    <geometry>
      <mesh filename="package://jamie_description/meshes/left_shoulder_link_1.stl" scale="0.001 0.001 0.001"/>
    </geometry>
    <material name="silver"/>
  </visual>
  <collision>
    <origin xyz="0.118164 0.053179 -0.133793" rpy="0 0 0"/>
    <geometry>
      <mesh filename="package://jamie_description/meshes/left_shoulder_link_1.stl" scale="0.001 0.001 0.001"/>
    </geometry>
  </collision>
</link>

<link name="chest_link_1">
  <inertial>
    <origin xyz="-1.1316457350710185e-07 0.02906330717635416 0.04592990519492751" rpy="0 0 0"/>
    <mass value="1.8523759675731215"/>
    <inertia ixx="0.001182" iyy="0.003891" izz="0.004278" ixy="-0.0" iyz="5.8e-05" ixz="-0.0"/>
  </inertial>
  <visual>
    <origin xyz="0.010588 0.057353 -0.084308" rpy="0 0 0"/>
    <geometry>
      <mesh filename="package://jamie_description/meshes/chest_link_1.stl" scale="0.001 0.001 0.001"/>
    </geometry>
    <material name="silver"/>
  </visual>
  <collision>
    <origin xyz="0.010588 0.057353 -0.084308" rpy="0 0 0"/>
    <geometry>
      <mesh filename="package://jamie_description/meshes/chest_link_1.stl" scale="0.001 0.001 0.001"/>
    </geometry>
  </collision>
</link>

<link name="spine_connector_link_1">
  <inertial>
    <origin xyz="-0.016506126643822533 0.00976530186829027 0.010210105914556483" rpy="0 0 0"/>
    <mass value="0.2675520479560331"/>
    <inertia ixx="0.000166" iyy="0.000125" izz="0.000109" ixy="1.4e-05" iyz="-1e-06" ixz="1e-06"/>
  </inertial>
  <visual>
    <origin xyz="-0.011912 0.043103 -0.084308" rpy="0 0 0"/>
    <geometry>
      <mesh filename="package://jamie_description/meshes/spine_connector_link_1.stl" scale="0.001 0.001 0.001"/>
    </geometry>
    <material name="silver"/>
  </visual>
  <collision>
    <origin xyz="-0.011912 0.043103 -0.084308" rpy="0 0 0"/>
    <geometry>
      <mesh filename="package://jamie_description/meshes/spine_connector_link_1.stl" scale="0.001 0.001 0.001"/>
    </geometry>
  </collision>
</link>

<link name="left_upper_leg_link_1">
  <inertial>
    <origin xyz="-0.011849592856818726 0.002829371668791672 -0.08923059026703958" rpy="0 0 0"/>
    <mass value="0.40754083950250325"/>
    <inertia ixx="0.001416" iyy="0.001457" izz="0.000338" ixy="-1.7e-05" iyz="9e-05" ixz="0.00022"/>
  </inertial>
  <visual>
    <origin xyz="0.054988 0.033917 0.144864" rpy="0 0 0"/>
    <geometry>
      <mesh filename="package://jamie_description/meshes/left_upper_leg_link_1.stl" scale="0.001 0.001 0.001"/>
    </geometry>
    <material name="silver"/>
  </visual>
  <collision>
    <origin xyz="0.054988 0.033917 0.144864" rpy="0 0 0"/>
    <geometry>
      <mesh filename="package://jamie_description/meshes/left_upper_leg_link_1.stl" scale="0.001 0.001 0.001"/>
    </geometry>
  </collision>
</link>

<link name="right_upper_leg_link_1">
  <inertial>
    <origin xyz="0.011849783032938543 0.002829371655435887 -0.08923059026985594" rpy="0 0 0"/>
    <mass value="0.40754083973100536"/>
    <inertia ixx="0.001416" iyy="0.001457" izz="0.000338" ixy="1.7e-05" iyz="9e-05" ixz="-0.00022"/>
  </inertial>
  <visual>
    <origin xyz="-0.031612 0.033917 0.144864" rpy="0 0 0"/>
    <geometry>
      <mesh filename="package://jamie_description/meshes/right_upper_leg_link_1.stl" scale="0.001 0.001 0.001"/>
    </geometry>
    <material name="silver"/>
  </visual>
  <collision>
    <origin xyz="-0.031612 0.033917 0.144864" rpy="0 0 0"/>
    <geometry>
      <mesh filename="package://jamie_description/meshes/right_upper_leg_link_1.stl" scale="0.001 0.001 0.001"/>
    </geometry>
  </collision>
</link>

<link name="spine_link_1">
  <inertial>
    <origin xyz="0.027174767465290472 0.0030521600876141017 0.08499963412321193" rpy="0 0 0"/>
    <mass value="0.2851299685332731"/>
    <inertia ixx="0.00083" iyy="0.00095" izz="0.000199" ixy="0.0" iyz="0.0" ixz="-0.0"/>
  </inertial>
  <visual>
    <origin xyz="0.038938 0.043103 0.085692" rpy="0 0 0"/>
    <geometry>
      <mesh filename="package://jamie_description/meshes/spine_link_1.stl" scale="0.001 0.001 0.001"/>
    </geometry>
    <material name="silver"/>
  </visual>
  <collision>
    <origin xyz="0.038938 0.043103 0.085692" rpy="0 0 0"/>
    <geometry>
      <mesh filename="package://jamie_description/meshes/spine_link_1.stl" scale="0.001 0.001 0.001"/>
    </geometry>
  </collision>
</link>

<link name="neck_servo_v1_1">
  <inertial>
    <origin xyz="0.004498756175713993 -0.024681281227217043 -0.00812866225710629" rpy="0 0 0"/>
    <mass value="0.25721902111029343"/>
    <inertia ixx="7.2e-05" iyy="4.5e-05" izz="4.3e-05" ixy="0.0" iyz="2e-06" ixz="0.0"/>
  </inertial>
  <visual>
    <origin xyz="0.015088 0.008497 -0.158408" rpy="0 0 0"/>
    <geometry>
      <mesh filename="package://jamie_description/meshes/neck_servo_v1_1.stl" scale="0.001 0.001 0.001"/>
    </geometry>
    <material name="silver"/>
  </visual>
  <collision>
    <origin xyz="0.015088 0.008497 -0.158408" rpy="0 0 0"/>
    <geometry>
      <mesh filename="package://jamie_description/meshes/neck_servo_v1_1.stl" scale="0.001 0.001 0.001"/>
    </geometry>
  </collision>
</link>

<link name="neck_link_1">
  <inertial>
    <origin xyz="7.906866862536846e-06 0.008823188656805377 0.007600003281340223" rpy="0 0 0"/>
    <mass value="0.09691779368254524"/>
    <inertia ixx="2.3e-05" iyy="5.3e-05" izz="5.3e-05" ixy="0.0" iyz="-1e-06" ixz="-0.0"/>
  </inertial>
  <visual>
    <origin xyz="0.010587 0.04293 -0.174208" rpy="0 0 0"/>
    <geometry>
      <mesh filename="package://jamie_description/meshes/neck_link_1.stl" scale="0.001 0.001 0.001"/>
    </geometry>
    <material name="silver"/>
  </visual>
  <collision>
    <origin xyz="0.010587 0.04293 -0.174208" rpy="0 0 0"/>
    <geometry>
      <mesh filename="package://jamie_description/meshes/neck_link_1.stl" scale="0.001 0.001 0.001"/>
    </geometry>
  </collision>
</link>

<link name="neck_nod_tilt_link_1">
  <inertial>
    <origin xyz="0.016876907608138172 -0.009827444811209469 0.010517825301487094" rpy="0 0 0"/>
    <mass value="0.2884047672762395"/>
    <inertia ixx="0.000176" iyy="0.000137" izz="0.000111" ixy="1.6e-05" iyz="-5e-06" ixz="1e-06"/>
  </inertial>
  <visual>
    <origin xyz="0.033573 0.026911 -0.199208" rpy="0 0 0"/>
    <geometry>
      <mesh filename="package://jamie_description/meshes/neck_nod_tilt_link_1.stl" scale="0.001 0.001 0.001"/>
    </geometry>
    <material name="silver"/>
  </visual>
  <collision>
    <origin xyz="0.033573 0.026911 -0.199208" rpy="0 0 0"/>
    <geometry>
      <mesh filename="package://jamie_description/meshes/neck_nod_tilt_link_1.stl" scale="0.001 0.001 0.001"/>
    </geometry>
  </collision>
</link>

<link name="eye_holder_link_1">
  <inertial>
    <origin xyz="5.747812279516609e-06 0.006610206761225312 -3.658776367987393e-07" rpy="0 0 0"/>
    <mass value="0.16148324488991492"/>
    <inertia ixx="6.3e-05" iyy="0.000324" izz="0.000261" ixy="0.0" iyz="-0.0" ixz="5e-06"/>
  </inertial>
  <visual>
    <origin xyz="0.011055 0.005826 -0.242708" rpy="0 0 0"/>
    <geometry>
      <mesh filename="package://jamie_description/meshes/eye_holder_link_1.stl" scale="0.001 0.001 0.001"/>
    </geometry>
    <material name="silver"/>
  </visual>
  <collision>
    <origin xyz="0.011055 0.005826 -0.242708" rpy="0 0 0"/>
    <geometry>
      <mesh filename="package://jamie_description/meshes/eye_holder_link_1.stl" scale="0.001 0.001 0.001"/>
    </geometry>
  </collision>
</link>

<link name="head_connector_link_1">
  <inertial>
    <origin xyz="-2.018643563084059e-05 -0.023606157816159382 0.0203984707204177" rpy="0 0 0"/>
    <mass value="0.10736239781961848"/>
    <inertia ixx="0.000111" iyy="2e-05" izz="0.000103" ixy="-0.0" iyz="-2e-06" ixz="-0.0"/>
  </inertial>
  <visual>
    <origin xyz="0.011061 0.01293 -0.220208" rpy="0 0 0"/>
    <geometry>
      <mesh filename="package://jamie_description/meshes/head_connector_link_1.stl" scale="0.001 0.001 0.001"/>
    </geometry>
    <material name="silver"/>
  </visual>
  <collision>
    <origin xyz="0.011061 0.01293 -0.220208" rpy="0 0 0"/>
    <geometry>
      <mesh filename="package://jamie_description/meshes/head_connector_link_1.stl" scale="0.001 0.001 0.001"/>
    </geometry>
  </collision>
</link>

<link name="right_shoulder_servo_v1_1">
  <inertial>
    <origin xyz="-0.00812860742899671 -0.02468076372691968 -0.004498749573111471" rpy="0 0 0"/>
    <mass value="0.2572190211102965"/>
    <inertia ixx="4.3e-05" iyy="4.5e-05" izz="7.2e-05" ixy="2e-06" iyz="-0.0" ixz="-0.0"/>
  </inertial>
  <visual>
    <origin xyz="-0.058137 0.006701 -0.13922" rpy="0 0 0"/>
    <geometry>
      <mesh filename="package://jamie_description/meshes/right_shoulder_servo_v1_1.stl" scale="0.001 0.001 0.001"/>
    </geometry>
    <material name="silver"/>
  </visual>
  <collision>
    <origin xyz="-0.058137 0.006701 -0.13922" rpy="0 0 0"/>
    <geometry>
      <mesh filename="package://jamie_description/meshes/right_shoulder_servo_v1_1.stl" scale="0.001 0.001 0.001"/>
    </geometry>
  </collision>
</link>

<link name="right_shoulder_connector_link_1">
  <inertial>
    <origin xyz="0.005752124062318106 0.009618723829080245 0.002431831375562188" rpy="0 0 0"/>
    <mass value="0.08077297877855137"/>
    <inertia ixx="3.5e-05" iyy="1.8e-05" izz="3.8e-05" ixy="0.0" iyz="-1e-06" ixz="1e-06"/>
  </inertial>
  <visual>
    <origin xyz="-0.073937 0.041134 -0.134719" rpy="0 0 0"/>
    <geometry>
      <mesh filename="package://jamie_description/meshes/right_shoulder_connector_link_1.stl" scale="0.001 0.001 0.001"/>
    </geometry>
    <material name="silver"/>
  </visual>
  <collision>
    <origin xyz="-0.073937 0.041134 -0.134719" rpy="0 0 0"/>
    <geometry>
      <mesh filename="package://jamie_description/meshes/right_shoulder_connector_link_1.stl" scale="0.001 0.001 0.001"/>
    </geometry>
  </collision>
</link>

<link name="upper_right_arm_servo_1">
  <inertial>
    <origin xyz="-2.510803230840186e-06 0.011732936046508276 -0.02530054127615601" rpy="0 0 0"/>
    <mass value="0.2572190211102965"/>
    <inertia ixx="7.2e-05" iyy="4.5e-05" izz="4.3e-05" ixy="0.0" iyz="2e-06" ixz="0.0"/>
  </inertial>
  <visual>
    <origin xyz="-0.097021 0.036387 -0.097848" rpy="0 0 0"/>
    <geometry>
      <mesh filename="package://jamie_description/meshes/upper_right_arm_servo_1.stl" scale="0.001 0.001 0.001"/>
    </geometry>
    <material name="silver"/>
  </visual>
  <collision>
    <origin xyz="-0.097021 0.036387 -0.097848" rpy="0 0 0"/>
    <geometry>
      <mesh filename="package://jamie_description/meshes/upper_right_arm_servo_1.stl" scale="0.001 0.001 0.001"/>
    </geometry>
  </collision>
</link>

<link name="right_upper_arm_link_1">
  <inertial>
    <origin xyz="-0.004123350154138353 -0.017587352029927915 -0.02655071795868074" rpy="0 0 0"/>
    <mass value="0.255754845328822"/>
    <inertia ixx="0.000327" iyy="0.000305" izz="0.000135" ixy="-0.0" iyz="-1.2e-05" ixz="1e-06"/>
  </inertial>
  <visual>
    <origin xyz="-0.10152 0.000671 -0.08255" rpy="0 0 0"/>
    <geometry>
      <mesh filename="package://jamie_description/meshes/right_upper_arm_link_1.stl" scale="0.001 0.001 0.001"/>
    </geometry>
    <material name="silver"/>
  </visual>
  <collision>
    <origin xyz="-0.10152 0.000671 -0.08255" rpy="0 0 0"/>
    <geometry>
      <mesh filename="package://jamie_description/meshes/right_upper_arm_link_1.stl" scale="0.001 0.001 0.001"/>
    </geometry>
  </collision>
</link>

<link name="right_forearm_servo_1">
  <inertial>
    <origin xyz="-0.010378123114656357 0.006383939661467209 -0.024261954643891036" rpy="0 0 0"/>
    <mass value="0.2572190211102965"/>
    <inertia ixx="4.3e-05" iyy="7.1e-05" izz="4.5e-05" ixy="-0.0" iyz="2e-06" ixz="2e-06"/>
  </inertial>
  <visual>
    <origin xyz="-0.108435 0.023995 -0.019347" rpy="0 0 0"/>
    <geometry>
      <mesh filename="package://jamie_description/meshes/right_forearm_servo_1.stl" scale="0.001 0.001 0.001"/>
    </geometry>
    <material name="silver"/>
  </visual>
  <collision>
    <origin xyz="-0.108435 0.023995 -0.019347" rpy="0 0 0"/>
    <geometry>
      <mesh filename="package://jamie_description/meshes/right_forearm_servo_1.stl" scale="0.001 0.001 0.001"/>
    </geometry>
  </collision>
</link>

<link name="forearm_right_v1_1">
  <inertial>
    <origin xyz="-0.019394005129541883 -0.006187519065597221 -0.04912253646367075" rpy="0 0 0"/>
    <mass value="0.17753961220642203"/>
    <inertia ixx="0.000376" iyy="0.000381" izz="7.2e-05" ixy="-8e-06" iyz="6.1e-05" ixz="3.4e-05"/>
  </inertial>
  <visual>
    <origin xyz="-0.121985 0.016858 0.014638" rpy="0 0 0"/>
    <geometry>
      <mesh filename="package://jamie_description/meshes/forearm_right_v1_1.stl" scale="0.001 0.001 0.001"/>
    </geometry>
    <material name="silver"/>
  </visual>
  <collision>
    <origin xyz="-0.121985 0.016858 0.014638" rpy="0 0 0"/>
    <geometry>
      <mesh filename="package://jamie_description/meshes/forearm_right_v1_1.stl" scale="0.001 0.001 0.001"/>
    </geometry>
  </collision>
</link>

<link name="left_shoulder_servo_1">
  <inertial>
    <origin xyz="0.008128392770885493 0.023799719432171376 0.00474899590886993" rpy="0 0 0"/>
    <mass value="0.2572190211102965"/>
    <inertia ixx="4.3e-05" iyy="4.5e-05" izz="7.2e-05" ixy="-2e-06" iyz="0.0" ixz="-0.0"/>
  </inertial>
  <visual>
    <origin xyz="0.079313 0.054953 -0.12932" rpy="0 0 0"/>
    <geometry>
      <mesh filename="package://jamie_description/meshes/left_shoulder_servo_1.stl" scale="0.001 0.001 0.001"/>
    </geometry>
    <material name="silver"/>
  </visual>
  <collision>
    <origin xyz="0.079313 0.054953 -0.12932" rpy="0 0 0"/>
    <geometry>
      <mesh filename="package://jamie_description/meshes/left_shoulder_servo_1.stl" scale="0.001 0.001 0.001"/>
    </geometry>
  </collision>
</link>

<link name="left_shoulder_connector_link_1">
  <inertial>
    <origin xyz="-0.005753141750530072 0.009742595834557 0.0018734256404009109" rpy="0 0 0"/>
    <mass value="0.08076633902558729"/>
    <inertia ixx="3.5e-05" iyy="1.8e-05" izz="3.8e-05" ixy="-0.0" iyz="-0.0" ixz="-1e-06"/>
  </inertial>
  <visual>
    <origin xyz="0.095113 0.040905 -0.134072" rpy="0 0 0"/>
    <geometry>
      <mesh filename="package://jamie_description/meshes/left_shoulder_connector_link_1.stl" scale="0.001 0.001 0.001"/>
    </geometry>
    <material name="silver"/>
  </visual>
  <collision>
    <origin xyz="0.095113 0.040905 -0.134072" rpy="0 0 0"/>
    <geometry>
      <mesh filename="package://jamie_description/meshes/left_shoulder_connector_link_1.stl" scale="0.001 0.001 0.001"/>
    </geometry>
  </collision>
</link>

<link name="upper_left_arm_servo_1">
  <inertial>
    <origin xyz="-2.877074061907736e-06 0.010252901008719402 -0.0259352898717696" rpy="0 0 0"/>
    <mass value="0.2572190211102965"/>
    <inertia ixx="7.2e-05" iyy="4.5e-05" izz="4.3e-05" ixy="0.0" iyz="2e-06" ixz="0.0"/>
  </inertial>
  <visual>
    <origin xyz="0.118197 0.038295 -0.096988" rpy="0 0 0"/>
    <geometry>
      <mesh filename="package://jamie_description/meshes/upper_left_arm_servo_1.stl" scale="0.001 0.001 0.001"/>
    </geometry>
    <material name="silver"/>
  </visual>
  <collision>
    <origin xyz="0.118197 0.038295 -0.096988" rpy="0 0 0"/>
    <geometry>
      <mesh filename="package://jamie_description/meshes/upper_left_arm_servo_1.stl" scale="0.001 0.001 0.001"/>
    </geometry>
  </collision>
</link>

<link name="left_forearm_servo_1">
  <inertial>
    <origin xyz="0.010377989755389824 0.00497564306234646 -0.024590058711966623" rpy="0 0 0"/>
    <mass value="0.2572190211102965"/>
    <inertia ixx="4.3e-05" iyy="7.2e-05" izz="4.5e-05" ixy="0.0" iyz="1e-06" ixz="-2e-06"/>
  </inertial>
  <visual>
    <origin xyz="0.129614 0.030456 -0.017903" rpy="0 0 0"/>
    <geometry>
      <mesh filename="package://jamie_description/meshes/left_forearm_servo_1.stl" scale="0.001 0.001 0.001"/>
    </geometry>
    <material name="silver"/>
  </visual>
  <collision>
    <origin xyz="0.129614 0.030456 -0.017903" rpy="0 0 0"/>
    <geometry>
      <mesh filename="package://jamie_description/meshes/left_forearm_servo_1.stl" scale="0.001 0.001 0.001"/>
    </geometry>
  </collision>
</link>

<link name="forearm_left_v1_1">
  <inertial>
    <origin xyz="0.01939387800689696 -0.009012982086464168 -0.048683876996780125" rpy="0 0 0"/>
    <mass value="0.17753962618878713"/>
    <inertia ixx="0.000376" iyy="0.000387" izz="6.6e-05" ixy="6e-06" iyz="4.2e-05" ixz="-3.5e-05"/>
  </inertial>
  <visual>
    <origin xyz="0.143164 0.025295 0.016437" rpy="0 0 0"/>
    <geometry>
      <mesh filename="package://jamie_description/meshes/forearm_left_v1_1.stl" scale="0.001 0.001 0.001"/>
    </geometry>
    <material name="silver"/>
  </visual>
  <collision>
    <origin xyz="0.143164 0.025295 0.016437" rpy="0 0 0"/>
    <geometry>
      <mesh filename="package://jamie_description/meshes/forearm_left_v1_1.stl" scale="0.001 0.001 0.001"/>
    </geometry>
  </collision>
</link>

<link name="left_upper_arm_link_1">
  <inertial>
    <origin xyz="0.004123243749002498 -0.019090350416492475 -0.025492083030674344" rpy="0 0 0"/>
    <mass value="0.2557548453425491"/>
    <inertia ixx="0.000327" iyy="0.000303" izz="0.000137" ixy="-0.0" iyz="-2.1e-05" ixz="-1e-06"/>
  </inertial>
  <visual>
    <origin xyz="0.122699 0.003522 -0.079655" rpy="0 0 0"/>
    <geometry>
      <mesh filename="package://jamie_description/meshes/left_upper_arm_link_1.stl" scale="0.001 0.001 0.001"/>
    </geometry>
    <material name="silver"/>
  </visual>
  <collision>
    <origin xyz="0.122699 0.003522 -0.079655" rpy="0 0 0"/>
    <geometry>
      <mesh filename="package://jamie_description/meshes/left_upper_arm_link_1.stl" scale="0.001 0.001 0.001"/>
    </geometry>
  </collision>
</link>

<link name="left_knee_servo_1">
  <inertial>
    <origin xyz="0.01037789378086855 -0.004498624814330811 -0.024681265256192964" rpy="0 0 0"/>
    <mass value="0.2572190211102965"/>
    <inertia ixx="4.3e-05" iyy="7.2e-05" izz="4.5e-05" ixy="0.0" iyz="-0.0" ixz="-2e-06"/>
  </inertial>
  <visual>
    <origin xyz="0.066624 0.029397 0.292205" rpy="0 0 0"/>
    <geometry>
      <mesh filename="package://jamie_description/meshes/left_knee_servo_1.stl" scale="0.001 0.001 0.001"/>
    </geometry>
    <material name="silver"/>
  </visual>
  <collision>
    <origin xyz="0.066624 0.029397 0.292205" rpy="0 0 0"/>
    <geometry>
      <mesh filename="package://jamie_description/meshes/left_knee_servo_1.stl" scale="0.001 0.001 0.001"/>
    </geometry>
  </collision>
</link>

<link name="left_lower_leg_link_1">
  <inertial>
    <origin xyz="0.023515277987629278 0.0045635213235817595 -0.07198270681693797" rpy="0 0 0"/>
    <mass value="0.3617681277031548"/>
    <inertia ixx="0.001335" iyy="0.00132" izz="0.000226" ixy="0.0" iyz="-6.8e-05" ixz="-6e-06"/>
  </inertial>
  <visual>
    <origin xyz="0.080174 0.033898 0.326638" rpy="0 0 0"/>
    <geometry>
      <mesh filename="package://jamie_description/meshes/left_lower_leg_link_1.stl" scale="0.001 0.001 0.001"/>
    </geometry>
    <material name="silver"/>
  </visual>
  <collision>
    <origin xyz="0.080174 0.033898 0.326638" rpy="0 0 0"/>
    <geometry>
      <mesh filename="package://jamie_description/meshes/left_lower_leg_link_1.stl" scale="0.001 0.001 0.001"/>
    </geometry>
  </collision>
</link>

<link name="left_ankle_servo_1">
  <inertial>
    <origin xyz="0.010377893780845047 -0.00449908416490016 -0.024681407818125167" rpy="0 0 0"/>
    <mass value="0.2572190211102965"/>
    <inertia ixx="4.3e-05" iyy="7.2e-05" izz="4.5e-05" ixy="0.0" iyz="-0.0" ixz="-2e-06"/>
  </inertial>
  <visual>
    <origin xyz="0.067674 0.028298 0.470038" rpy="0 0 0"/>
    <geometry>
      <mesh filename="package://jamie_description/meshes/left_ankle_servo_1.stl" scale="0.001 0.001 0.001"/>
    </geometry>
    <material name="silver"/>
  </visual>
  <collision>
    <origin xyz="0.067674 0.028298 0.470038" rpy="0 0 0"/>
    <geometry>
      <mesh filename="package://jamie_description/meshes/left_ankle_servo_1.stl" scale="0.001 0.001 0.001"/>
    </geometry>
  </collision>
</link>

<link name="left_foot_link_1">
  <inertial>
    <origin xyz="0.021983260519152656 0.026383158236471093 -0.0229144258498577" rpy="0 0 0"/>
    <mass value="0.047635684999489704"/>
    <inertia ixx="8.3e-05" iyy="1.9e-05" izz="9e-05" ixy="3e-06" iyz="4e-06" ixz="-0.0"/>
  </inertial>
  <visual>
    <origin xyz="0.081224 0.0328 0.504471" rpy="0 0 0"/>
    <geometry>
      <mesh filename="package://jamie_description/meshes/left_foot_link_1.stl" scale="0.001 0.001 0.001"/>
    </geometry>
    <material name="silver"/>
  </visual>
  <collision>
    <origin xyz="0.081224 0.0328 0.504471" rpy="0 0 0"/>
    <geometry>
      <mesh filename="package://jamie_description/meshes/left_foot_link_1.stl" scale="0.001 0.001 0.001"/>
    </geometry>
  </collision>
</link>

<link name="right_knee_servo_1">
  <inertial>
    <origin xyz="-0.010278358850363885 -0.004500879332427404 -0.024681265256203677" rpy="0 0 0"/>
    <mass value="0.2572190211102965"/>
    <inertia ixx="4.3e-05" iyy="7.2e-05" izz="4.5e-05" ixy="0.0" iyz="0.0" ixz="2e-06"/>
  </inertial>
  <visual>
    <origin xyz="-0.043248 0.029397 0.292205" rpy="0 0 0"/>
    <geometry>
      <mesh filename="package://jamie_description/meshes/right_knee_servo_1.stl" scale="0.001 0.001 0.001"/>
    </geometry>
    <material name="silver"/>
  </visual>
  <collision>
    <origin xyz="-0.043248 0.029397 0.292205" rpy="0 0 0"/>
    <geometry>
      <mesh filename="package://jamie_description/meshes/right_knee_servo_1.stl" scale="0.001 0.001 0.001"/>
    </geometry>
  </collision>
</link>

<link name="right_lower_leg_link_1">
  <inertial>
    <origin xyz="-0.023515842298494176 0.004563212335493196 -0.07198302999537853" rpy="0 0 0"/>
    <mass value="0.3617641931033871"/>
    <inertia ixx="0.001335" iyy="0.00132" izz="0.000226" ixy="-0.0" iyz="-6.8e-05" ixz="6e-06"/>
  </inertial>
  <visual>
    <origin xyz="-0.056898 0.033895 0.326638" rpy="0 0 0"/>
    <geometry>
      <mesh filename="package://jamie_description/meshes/right_lower_leg_link_1.stl" scale="0.001 0.001 0.001"/>
    </geometry>
    <material name="silver"/>
  </visual>
  <collision>
    <origin xyz="-0.056898 0.033895 0.326638" rpy="0 0 0"/>
    <geometry>
      <mesh filename="package://jamie_description/meshes/right_lower_leg_link_1.stl" scale="0.001 0.001 0.001"/>
    </geometry>
  </collision>
</link>

<link name="right_ankle_servo_1">
  <inertial>
    <origin xyz="-0.010378358850152168 0.004498580018135266 -0.024681407818113066" rpy="0 0 0"/>
    <mass value="0.2572190211102965"/>
    <inertia ixx="4.3e-05" iyy="7.2e-05" izz="4.5e-05" ixy="0.0" iyz="0.0" ixz="2e-06"/>
  </inertial>
  <visual>
    <origin xyz="-0.044398 0.037295 0.470038" rpy="0 0 0"/>
    <geometry>
      <mesh filename="package://jamie_description/meshes/right_ankle_servo_1.stl" scale="0.001 0.001 0.001"/>
    </geometry>
    <material name="silver"/>
  </visual>
  <collision>
    <origin xyz="-0.044398 0.037295 0.470038" rpy="0 0 0"/>
    <geometry>
      <mesh filename="package://jamie_description/meshes/right_ankle_servo_1.stl" scale="0.001 0.001 0.001"/>
    </geometry>
  </collision>
</link>

<link name="right_foot_link_1">
  <inertial>
    <origin xyz="-0.021983693931272683 0.02638300421014424 -0.022914426539675126" rpy="0 0 0"/>
    <mass value="0.04763567628033751"/>
    <inertia ixx="8.3e-05" iyy="1.9e-05" izz="9e-05" ixy="-3e-06" iyz="4e-06" ixz="0.0"/>
  </inertial>
  <visual>
    <origin xyz="-0.057948 0.032794 0.504471" rpy="0 0 0"/>
    <geometry>
      <mesh filename="package://jamie_description/meshes/right_foot_link_1.stl" scale="0.001 0.001 0.001"/>
    </geometry>
    <material name="silver"/>
  </visual>
  <collision>
    <origin xyz="-0.057948 0.032794 0.504471" rpy="0 0 0"/>
    <geometry>
      <mesh filename="package://jamie_description/meshes/right_foot_link_1.stl" scale="0.001 0.001 0.001"/>
    </geometry>
  </collision>
</link>

<joint name="Revolute 4" type="revolute">
  <origin xyz="0.023051 -0.012237 -0.000987" rpy="0 0 0"/>
  <parent link="right_shoulder_connector_link_1"/>
  <child link="right_shoulder_link_1"/>
  <axis xyz="0.0 0.997036 0.076933"/>
  <limit upper="0.436332" lower="-2.70526" effort="100" velocity="100"/>
</joint>

<joint name="Revolute 8" type="revolute">
  <origin xyz="-0.023051 -0.012274 -0.000279" rpy="0 0 0"/>
  <parent link="left_shoulder_connector_link_1"/>
  <child link="left_shoulder_link_1"/>
  <axis xyz="0.0 0.999815 0.019247"/>
  <limit upper="2.70526" lower="-0.436332" effort="100" velocity="100"/>
</joint>

<joint name="Revolute 11" type="revolute">
  <origin xyz="-0.0225 -0.01425 0.0" rpy="0 0 0"/>
  <parent link="spine_connector_link_1"/>
  <child link="chest_link_1"/>
  <axis xyz="0.0 1.0 0.0"/>
  <limit upper="0.698132" lower="-0.698132" effort="100" velocity="100"/>
</joint>

<joint name="Revolute 12" type="revolute">
  <origin xyz="0.05085 0.0 0.17" rpy="0 0 0"/>
  <parent link="spine_link_1"/>
  <child link="spine_connector_link_1"/>
  <axis xyz="1.0 -0.0 -0.0"/>
  <limit upper="0.698132" lower="-0.698132" effort="100" velocity="100"/>
</joint>

<joint name="Revolute 14" type="revolute">
  <origin xyz="-0.054988 -0.033917 -0.144864" rpy="0 0 0"/>
  <parent link="base_link"/>
  <child link="left_upper_leg_link_1"/>
  <axis xyz="-1.0 0.0 -0.0"/>
  <limit upper="0.0" lower="-1.396263" effort="100" velocity="100"/>
</joint>

<joint name="Revolute 17" type="revolute">
  <origin xyz="0.031612 -0.033917 -0.144864" rpy="0 0 0"/>
  <parent link="base_link"/>
  <child link="right_upper_leg_link_1"/>
  <axis xyz="-1.0 0.0 -0.0"/>
  <limit upper="0.0" lower="-1.396263" effort="100" velocity="100"/>
</joint>

<joint name="Revolute 1" type="fixed">
  <origin xyz="-0.038938 -0.043103 -0.085692" rpy="0 0 0"/>
  <parent link="base_link"/>
  <child link="spine_link_1"/>
</joint>

<joint name="Rigid 1" type="fixed">
  <origin xyz="-0.0045 0.048856 0.0741" rpy="0 0 0"/>
  <parent link="chest_link_1"/>
  <child link="neck_servo_v1_1"/>
</joint>

<joint name="Revolute 6" type="revolute">
  <origin xyz="0.004501 -0.034433 0.0158" rpy="0 0 0"/>
  <parent link="neck_servo_v1_1"/>
  <child link="neck_link_1"/>
  <axis xyz="-0.0 0.0 -1.0"/>
  <limit upper="1.570796" lower="-1.570796" effort="100" velocity="100"/>
</joint>

<joint name="Revolute 7" type="revolute">
  <origin xyz="-0.022986 0.016019 0.025" rpy="0 0 0"/>
  <parent link="neck_link_1"/>
  <child link="neck_nod_tilt_link_1"/>
  <axis xyz="-1.0 0.000856 0.0"/>
  <limit upper="0.349066" lower="-0.349066" effort="100" velocity="100"/>
</joint>

<joint name="Rigid 2" type="fixed">
  <origin xyz="6e-06 0.007104 0.0225" rpy="0 0 0"/>
  <parent link="head_connector_link_1"/>
  <child link="eye_holder_link_1"/>
</joint>

<joint name="Revolute 13" type="revolute">
  <origin xyz="0.022512 0.013981 0.021" rpy="0 0 0"/>
  <parent link="neck_nod_tilt_link_1"/>
  <child link="head_connector_link_1"/>
  <axis xyz="-0.000856 -1.0 0.0"/>
  <limit upper="1.570796" lower="-1.570796" effort="100" velocity="100"/>
</joint>

<joint name="Rigid 3" type="fixed">
  <origin xyz="0.068725 0.050652 0.054912" rpy="0 0 0"/>
  <parent link="chest_link_1"/>
  <child link="right_shoulder_servo_v1_1"/>
</joint>

<joint name="Revolute 3" type="revolute">
  <origin xyz="0.0158 -0.034433 -0.004501" rpy="0 0 0"/>
  <parent link="right_shoulder_servo_v1_1"/>
  <child link="right_shoulder_connector_link_1"/>
  <axis xyz="-1.0 0.0 0.0"/>
  <limit upper="0.0" lower="-3.141593" effort="100" velocity="100"/>
</joint>

<joint name="Revolute 21" type="revolute">
  <origin xyz="3.3e-05 0.016984 -0.035884" rpy="0 0 0"/>
  <parent link="right_shoulder_link_1"/>
  <child link="upper_right_arm_servo_1"/>
  <axis xyz="-0.0 0.076933 -0.997036"/>
  <limit upper="1.570796" lower="-1.570796" effort="100" velocity="100"/>
</joint>

<joint name="Rigid 4" type="fixed">
  <origin xyz="0.004499 0.035716 -0.015298" rpy="0 0 0"/>
  <parent link="upper_right_arm_servo_1"/>
  <child link="right_upper_arm_link_1"/>
</joint>

<joint name="Rigid 5" type="fixed">
  <origin xyz="0.006915 -0.023324 -0.063203" rpy="0 0 0"/>
  <parent link="right_upper_arm_link_1"/>
  <child link="right_forearm_servo_1"/>
</joint>

<joint name="Revolute 22" type="revolute">
  <origin xyz="0.01355 0.007137 -0.033985" rpy="0 0 0"/>
  <parent link="right_forearm_servo_1"/>
  <child link="forearm_right_v1_1"/>
  <axis xyz="-1.0 0.0 0.0"/>
  <limit upper="0.0" lower="-2.530727" effort="100" velocity="100"/>
</joint>

<joint name="Rigid 6" type="fixed">
  <origin xyz="-0.068725 0.0024 0.045012" rpy="0 0 0"/>
  <parent link="chest_link_1"/>
  <child link="left_shoulder_servo_1"/>
</joint>

<joint name="Revolute 20" type="revolute">
  <origin xyz="-0.0158 0.014048 0.004752" rpy="0 0 0"/>
  <parent link="left_shoulder_servo_1"/>
  <child link="left_shoulder_connector_link_1"/>
  <axis xyz="1.0 -0.0 -0.0"/>
  <limit upper="3.141593" lower="0.0" effort="100" velocity="100"/>
</joint>

<joint name="Revolute 9" type="revolute">
  <origin xyz="-3.3e-05 0.014884 -0.036805" rpy="0 0 0"/>
  <parent link="left_shoulder_link_1"/>
  <child link="upper_left_arm_servo_1"/>
  <axis xyz="-0.0 -0.019247 0.999815"/>
  <limit upper="1.570796" lower="-1.570796" effort="100" velocity="100"/>
</joint>

<joint name="Rigid 8" type="fixed">
  <origin xyz="-0.006915 -0.026934 -0.061752" rpy="0 0 0"/>
  <parent link="left_upper_arm_link_1"/>
  <child link="left_forearm_servo_1"/>
</joint>

<joint name="Revolute 2" type="revolute">
  <origin xyz="-0.01355 0.005161 -0.03434" rpy="0 0 0"/>
  <parent link="left_forearm_servo_1"/>
  <child link="forearm_left_v1_1"/>
  <axis xyz="1.0 -0.0 0.0"/>
  <limit upper="2.530727" lower="0.0" effort="100" velocity="100"/>
</joint>

<joint name="Rigid 7" type="fixed">
  <origin xyz="-0.004502 0.034773 -0.017333" rpy="0 0 0"/>
  <parent link="upper_left_arm_servo_1"/>
  <child link="left_upper_arm_link_1"/>
</joint>

<joint name="Rigid 9" type="fixed">
  <origin xyz="-0.011636 0.00452 -0.147341" rpy="0 0 0"/>
  <parent link="left_upper_leg_link_1"/>
  <child link="left_knee_servo_1"/>
</joint>

<joint name="Revolute 5" type="revolute">
  <origin xyz="-0.01355 -0.004501 -0.034433" rpy="0 0 0"/>
  <parent link="left_knee_servo_1"/>
  <child link="left_lower_leg_link_1"/>
  <axis xyz="1.0 -0.0 -0.0"/>
  <limit upper="0.0" lower="-1.658063" effort="100" velocity="100"/>
</joint>

<joint name="Rigid 10" type="fixed">
  <origin xyz="0.0125 0.0056 -0.1434" rpy="0 0 0"/>
  <parent link="left_lower_leg_link_1"/>
  <child link="left_ankle_servo_1"/>
</joint>

<joint name="Revolute 10" type="revolute">
  <origin xyz="-0.01355 -0.004502 -0.034433" rpy="0 0 0"/>
  <parent link="left_ankle_servo_1"/>
  <child link="left_foot_link_1"/>
  <axis xyz="1.0 -0.0 -0.0"/>
  <limit upper="0.785398" lower="-0.523599" effort="100" velocity="100"/>
</joint>

<joint name="Rigid 11" type="fixed">
  <origin xyz="0.011636 0.00452 -0.147341" rpy="0 0 0"/>
  <parent link="right_upper_leg_link_1"/>
  <child link="right_knee_servo_1"/>
</joint>

<joint name="Revolute 18" type="revolute">
  <origin xyz="0.01365 -0.004498 -0.034433" rpy="0 0 0"/>
  <parent link="right_knee_servo_1"/>
  <child link="right_lower_leg_link_1"/>
  <axis xyz="-1.0 0.0 0.0"/>
  <limit upper="1.658063" lower="0.0" effort="100" velocity="100"/>
</joint>

<joint name="Rigid 12" type="fixed">
  <origin xyz="-0.0125 -0.0034 -0.1434" rpy="0 0 0"/>
  <parent link="right_lower_leg_link_1"/>
  <child link="right_ankle_servo_1"/>
</joint>

<joint name="Revolute 19" type="revolute">
  <origin xyz="0.01355 0.004501 -0.034433" rpy="0 0 0"/>
  <parent link="right_ankle_servo_1"/>
  <child link="right_foot_link_1"/>
  <axis xyz="-1.0 0.0 -0.0"/>
  <limit upper="0.785398" lower="-0.523599" effort="100" velocity="100"/>
</joint>

</robot>
